<?xml version="1.0" ?>
<!-- =================================================================================== -->
<!-- |    This document was autogenerated by xacro from dlr_miiwa.urdf.xacro           | -->
<!-- |    EDITING THIS FILE BY HAND IS NOT RECOMMENDED                                 | -->
<!-- =================================================================================== -->
<robot name="dlr_miiwa" xmlns:controller="http://playerstage.sourceforge.net/gazebo/xmlschema/#controller" xmlns:interface="http://playerstage.sourceforge.net/gazebo/xmlschema/#interface" xmlns:sensor="http://playerstage.sourceforge.net/gazebo/xmlschema/#sensor" xmlns:xacro="http://www.ros.org/wiki/xacro">
  <!-- Import Rviz colors -->
  <material name="Black">
    <color rgba="0.0 0.0 0.0 1.0"/>
  </material>
  <material name="Blue">
    <color rgba="0.0 0.0 0.8 1.0"/>
  </material>
  <material name="Green">
    <color rgba="0.0 0.8 0.0 1.0"/>
  </material>
  <material name="Grey">
    <color rgba="0.2 0.2 0.2 1.0"/>
  </material>
  <material name="Light Grey">
    <color rgba="0.6 0.6 0.6 1.0"/>
  </material>
  <material name="Orange">
    <color rgba="1.0 0.423529411765 0.0392156862745 1.0"/>
  </material>
  <material name="Brown">
    <color rgba="0.870588235294 0.811764705882 0.764705882353 1.0"/>
  </material>
  <material name="Red">
    <color rgba="0.8 0.0 0.0 1.0"/>
  </material>
  <material name="White">
    <color rgba="1.0 1.0 1.0 1.0"/>
  </material>
  <!-- The following included files set up definitions of parts of the robot body -->
  <!-- Import Gazebo plugins -->
  <gazebo>
    <plugin filename="libgazebo_ros_control.so" name="gazebo_ros_controller">
      <robotNamespace>/dlr_miiwa</robotNamespace>
    </plugin>
  </gazebo>
  <!--xacro:include filename="$(find miiwa)/gazebo/gazebo.urdf.xacro"/-->
  <!--xacro:include filename="$(find lbr_iiwa_description)/gazebo/gazebo.urdf.xacro"/-->
  <!--xacro:include filename="$(find schunk_pw70)/gazebo/gazebo.urdf.xacro"/-->
  <!--xacro:include filename="$(find schunk_wsg50)/gazebo/gazebo.urdf.xacro"/-->
  <!-- Import urdf macros -->
  <!-- miiwa base -->
  <!-- Import all Gazebo-customization elements, including Gazebo colors -->
  <!-- Import Transmissions -->
  <!-- iiwa -->
  <!-- Import all Gazebo-customization elements, including Gazebo colors -->
  <!-- Import Transmissions -->
  <!-- Include Utilities -->
  <!-- The following macros are adapted from the LWR 4 definitions of the RCPRG - https://github.com/RCPRG-ros-pkg/lwr_robot -->
  <!--Little helper macros to define the inertia matrix needed for links.-->
  <!--Cuboid-->
  <!--Cylinder: length is along the y-axis! -->
  <!-- some constants -->
  <!-- <xacro:property name="safety_controller_k_pos" value="100" />
  <xacro:property name="safety_controller_k_vel" value="2" /> -->
  <!-- schunk_wsg50 -->
  <!-- Import all Gazebo-customization elements, including Gazebo colors -->
  <!-- Import Transmissions -->
  <!-- schunk_pw70 -->
  <!-- Import all Gazebo-customization elements, including Gazebo colors -->
  <!-- Import Transmissions -->
  <!-- pan-tilt_mast -->
  <!-- cameras -->
  <!-- Import all Gazebo-customization elements, including Gazebo colors -->
  <!-- Parameters are for mako g-125 -->
  <!-- Construct the dlr_miiwa from parts -->
  <!-- Base frame to anchor the robot in the world -->
  <link name="base_link"/>
  <!-- miiwa mobile base -->
  <joint name="miiwa_fixed_base_joint" type="fixed">
    <child link="miiwa_virtual_link_0"/>
    <parent link="base_link"/>
  </joint>
  <link name="miiwa_virtual_link_0">
    <visual>
      <origin rpy="0 0 0" xyz="0 0 0.1"/>
      <geometry>
        <box size="0.001 0.001 0.001"/>
      </geometry>
    </visual>
    <collision>
      <origin rpy="0 0 0" xyz="0 0 0.1"/>
      <geometry>
        <box size="0.001 0.001 0.001"/>
      </geometry>
    </collision>
    <inertial>
      <mass value="0.001"/>
      <inertia ixx="1.0" ixy="0.0" ixz="0.0" iyy="1.0" iyz="0.0" izz="1.0"/>
    </inertial>
  </link>
  <joint name="miiwa_joint_x" type="prismatic">
    <origin rpy="0 0 0" xyz="0 0 0"/>
    <axis xyz="1 0 0"/>
    <limit effort="1.0" lower="-100.0" upper="100.0" velocity="1.0"/>
    <parent link="miiwa_virtual_link_0"/>
    <child link="miiwa_virtual_link_1"/>
  </joint>
  <link name="miiwa_virtual_link_1">
    <visual>
      <origin rpy="0 0 0" xyz="0 0 0.1"/>
      <geometry>
        <box size="0.001 0.001 0.001"/>
      </geometry>
    </visual>
    <collision>
      <origin rpy="0 0 0" xyz="0 0 0.1"/>
      <geometry>
        <box size="0.001 0.001 0.001"/>
      </geometry>
    </collision>
    <inertial>
      <mass value="0.001"/>
      <inertia ixx="1.0" ixy="0.0" ixz="0.0" iyy="1.0" iyz="0.0" izz="1.0"/>
    </inertial>
  </link>
  <joint name="miiwa_joint_y" type="prismatic">
    <origin rpy="0 0 0" xyz="0 0 0"/>
    <axis xyz="0 1 0"/>
    <limit effort="1.0" lower="-100.0" upper="100.0" velocity="1.0"/>
    <parent link="miiwa_virtual_link_1"/>
    <child link="miiwa_virtual_link_2"/>
  </joint>
  <link name="miiwa_virtual_link_2">
    <visual>
      <origin rpy="0 0 0" xyz="0 0 0.1"/>
      <geometry>
        <box size="0.001 0.001 0.001"/>
      </geometry>
    </visual>
    <collision>
      <origin rpy="0 0 0" xyz="0 0 0.1"/>
      <geometry>
        <box size="0.001 0.001 0.001"/>
      </geometry>
    </collision>
    <inertial>
      <mass value="0.001"/>
      <inertia ixx="1.0" ixy="0.0" ixz="0.0" iyy="1.0" iyz="0.0" izz="1.0"/>
    </inertial>
  </link>
  <joint name="miiwa_joint_theta" type="continuous">
    <origin rpy="0 0 0" xyz="0 0 0"/>
    <axis xyz="0 0 1"/>
    <limit effort="1.0" velocity="1.0"/>
    <parent link="miiwa_virtual_link_2"/>
    <child link="miiwa_link"/>
  </joint>
  <link name="miiwa_link">
    <visual>
      <geometry>
        <mesh filename="package://miiwa/meshes/miiwa.stl"/>
      </geometry>
      <material name="Orange"/>
    </visual>
    <collision>
      <geometry>
        <mesh filename="package://miiwa/meshes/miiwa_collision.stl"/>
      </geometry>
      <material name="Orange"/>
    </collision>
    <inertial>
      <mass value="40.0"/>
      <inertia ixx="1.0" ixy="0.0" ixz="0.0" iyy="1.0" iyz="0.0" izz="1.0"/>
    </inertial>
  </link>
  <joint name="miiwa_left_iiwa_mount_joint" type="fixed">
    <origin rpy="0 0 1.5707963267948966" xyz="0.370 0.160 0.925"/>
    <parent link="miiwa_link"/>
    <child link="miiwa_left_iiwa_mount_link"/>
  </joint>
  <link name="miiwa_left_iiwa_mount_link"/>
  <joint name="miiwa_right_iiwa_mount_joint" type="fixed">
    <origin rpy="0 0 -1.5707963267948966" xyz="0.370 -0.160 0.925"/>
    <parent link="miiwa_link"/>
    <child link="miiwa_right_iiwa_mount_link"/>
  </joint>
  <link name="miiwa_right_iiwa_mount_link"/>
  <joint name="miiwa_mast_mount_joint" type="fixed">
    <origin rpy="0 0 0" xyz="-0.470 0.230 0.925"/>
    <parent link="miiwa_link"/>
    <child link="miiwa_link_mast_mount"/>
  </joint>
  <link name="miiwa_link_mast_mount"/>
  <!--Extensions -->
  <!-- Link0 -->
  <gazebo reference="miiwa_link">
    <material>Gazebo/Orange</material>
    <mu1>0.2</mu1>
    <mu2>0.2</mu2>
  </gazebo>
  <gazebo reference="camera_link">
    <sensor name="camera1" type="camera">
      <update_rate>30.0</update_rate>
      <camera name="head">
        <horizontal_fov>1.3962634</horizontal_fov>
        <image>
          <width>800</width>
          <height>800</height>
          <format>R8G8B8</format>
        </image>
      </camera>
      <plugin filename="libgazebo_ros_camera.so" name="camera_controller">
        <alwaysOn>true</alwaysOn>
        <updateRate>30.0</updateRate>
        <cameraName>camera1</cameraName>
        <imageTopicName>image_raw</imageTopicName>
        <cameraInfoTopicName>camera_info</cameraInfoTopicName>
        <frameName>camera_link</frameName>
      </plugin>
    </sensor>
  </gazebo>
  <transmission name="miiwa_tran_x">
    <type>transmission_interface/SimpleTransmission</type>
    <joint name="miiwa_joint_x">
      <hardwareInterface>PositionJointInterface</hardwareInterface>
    </joint>
    <actuator name="miiwa_motor_x">
      <hardwareInterface>PositionJointInterface</hardwareInterface>
      <mechanicalReduction>1</mechanicalReduction>
    </actuator>
  </transmission>
  <transmission name="miiwa_tran_y">
    <type>transmission_interface/SimpleTransmission</type>
    <joint name="miiwa_joint_y">
      <hardwareInterface>PositionJointInterface</hardwareInterface>
    </joint>
    <actuator name="miiwa_motor_y">
      <hardwareInterface>PositionJointInterface</hardwareInterface>
      <mechanicalReduction>1</mechanicalReduction>
    </actuator>
  </transmission>
  <transmission name="miiwa_tran_theta">
    <type>transmission_interface/SimpleTransmission</type>
    <joint name="miiwa_joint_theta">
      <hardwareInterface>PositionJointInterface</hardwareInterface>
    </joint>
    <actuator name="miiwa_motor_theta">
      <hardwareInterface>PositionJointInterface</hardwareInterface>
      <mechanicalReduction>1</mechanicalReduction>
    </actuator>
  </transmission>
  <!-- lbr iiwa manipulator -->
  <!--joint between {parent} and link_0-->
  <joint name="miiwa_left_iiwa_mount_link_joint" type="fixed">
    <origin rpy="0.0 0.0 0.0" xyz="0 0 0"/>
    <parent link="miiwa_left_iiwa_mount_link"/>
    <child link="lbr_iiwa_link_0"/>
  </joint>
  <link name="lbr_iiwa_link_0">
    <inertial>
      <origin rpy="0 0 0" xyz="-0.1 0 0.07"/>
      <mass value="5"/>
      <inertia ixx="0.05" ixy="0" ixz="0" iyy="0.06" iyz="0" izz="0.03"/>
    </inertial>
    <visual>
      <origin rpy="0 0 0" xyz="0 0 0"/>
      <geometry>
        <mesh filename="package://lbr_iiwa_description/meshes/link_0.stl"/>
      </geometry>
      <material name="Grey"/>
    </visual>
    <collision>
      <origin rpy="0 0 0" xyz="0 0 0"/>
      <geometry>
        <mesh filename="package://lbr_iiwa_description/meshes/coarse/link_0.stl"/>
      </geometry>
      <material name="Grey"/>
    </collision>
    <self_collision_checking>
      <origin rpy="0 0 0" xyz="0 0 0"/>
      <geometry>
        <capsule length="0.25" radius="0.15"/>
      </geometry>
    </self_collision_checking>
  </link>
  <!-- joint between link_0 and link_1 -->
  <joint name="lbr_iiwa_joint_1" type="revolute">
    <parent link="lbr_iiwa_link_0"/>
    <child link="lbr_iiwa_link_1"/>
    <origin rpy="0 0 0" xyz="0 0 0.1575"/>
    <axis xyz="0 0 1"/>
    <limit effort="300" lower="-2.96705972839" upper="2.96705972839" velocity="10"/>
    <!--   <safety_controller soft_lower_limit="${-168 * M_PI / 180}"
           soft_upper_limit="${168 * M_PI / 180}"
           k_position="${safety_controller_k_pos}"
           k_velocity="${safety_controller_k_vel}"/> -->
    <dynamics damping="0.5"/>
  </joint>
  <link name="lbr_iiwa_link_1">
    <inertial>
      <origin rpy="0 0 0" xyz="0 -0.03 0.12"/>
      <mass value="4"/>
      <inertia ixx="0.1" ixy="0" ixz="0" iyy="0.09" iyz="0" izz="0.02"/>
    </inertial>
    <visual>
      <origin rpy="0 0 0" xyz="0 0 0"/>
      <geometry>
        <mesh filename="package://lbr_iiwa_description/meshes/link_1.stl"/>
      </geometry>
      <material name="Orange"/>
    </visual>
    <collision>
      <origin rpy="0 0 0" xyz="0 0 0"/>
      <geometry>
        <mesh filename="package://lbr_iiwa_description/meshes/coarse/link_1.stl"/>
      </geometry>
      <material name="Orange"/>
    </collision>
  </link>
  <!-- joint between link_1 and link_2 -->
  <joint name="lbr_iiwa_joint_2" type="revolute">
    <parent link="lbr_iiwa_link_1"/>
    <child link="lbr_iiwa_link_2"/>
    <origin rpy="0 0 0" xyz="0 0 0.2025"/>
    <axis xyz="0 1 0"/>
    <limit effort="300" lower="-2.09439510239" upper="2.09439510239" velocity="10"/>
    <!-- <safety_controller soft_lower_limit="${-118 * PI / 180}"
           soft_upper_limit="${118 * PI / 180}"
           k_position="${safety_controller_k_pos}"
           k_velocity="${safety_controller_k_vel}"/> -->
    <dynamics damping="0.5"/>
  </joint>
  <link name="lbr_iiwa_link_2">
    <inertial>
      <origin rpy="0 0 0" xyz="0 0.04 0.06"/>
      <mass value="4"/>
      <inertia ixx="0.05" ixy="0" ixz="0" iyy="0.04" iyz="0" izz="0.02"/>
    </inertial>
    <visual>
      <origin rpy="0 0 0" xyz="0 0 0"/>
      <geometry>
        <mesh filename="package://lbr_iiwa_description/meshes/link_2.stl"/>
      </geometry>
      <material name="Orange"/>
    </visual>
    <collision>
      <origin rpy="0 0 0" xyz="0 0 0"/>
      <geometry>
        <mesh filename="package://lbr_iiwa_description/meshes/coarse/link_2.stl"/>
      </geometry>
      <material name="Orange"/>
    </collision>
  </link>
  <!-- joint between link_2 and link_3 -->
  <joint name="lbr_iiwa_joint_3" type="revolute">
    <parent link="lbr_iiwa_link_2"/>
    <child link="lbr_iiwa_link_3"/>
    <origin rpy="0 0 0" xyz="0 0 0.2045"/>
    <axis xyz="0 0 1"/>
    <limit effort="300" lower="-2.96705972839" upper="2.96705972839" velocity="10"/>
    <!-- <safety_controller soft_lower_limit="${-118 * PI / 180}"
           soft_upper_limit="${118 * PI / 180}"
           k_position="${safety_controller_k_pos}"
           k_velocity="${safety_controller_k_vel}"/> -->
    <dynamics damping="0.5"/>
  </joint>
  <link name="lbr_iiwa_link_3">
    <inertial>
      <origin rpy="0 0 0" xyz="0 0.03 0.13"/>
      <mass value="3"/>
      <inertia ixx="0.08" ixy="0" ixz="0" iyy="0.07" iyz="0" izz="0.01"/>
    </inertial>
    <visual>
      <origin rpy="0 0 0" xyz="0 0 0"/>
      <geometry>
        <mesh filename="package://lbr_iiwa_description/meshes/link_3.stl"/>
      </geometry>
      <material name="Orange"/>
    </visual>
    <collision>
      <origin rpy="0 0 0" xyz="0 0 0"/>
      <geometry>
        <mesh filename="package://lbr_iiwa_description/meshes/coarse/link_3.stl"/>
      </geometry>
      <material name="Orange"/>
    </collision>
  </link>
  <!-- joint between link_3 and link_4 -->
  <joint name="lbr_iiwa_joint_4" type="revolute">
    <parent link="lbr_iiwa_link_3"/>
    <child link="lbr_iiwa_link_4"/>
    <origin rpy="0 0 0" xyz="0 0 0.2155"/>
    <axis xyz="0 1 0"/>
    <limit effort="300" lower="-2.09439510239" upper="2.09439510239" velocity="10"/>
    <!-- <safety_controller soft_lower_limit="${-118 * PI / 180}"
           soft_upper_limit="${118 * PI / 180}"
           k_position="${safety_controller_k_pos}"
           k_velocity="${safety_controller_k_vel}"/> -->
    <dynamics damping="0.5"/>
  </joint>
  <link name="lbr_iiwa_link_4">
    <inertial>
      <origin rpy="0 0 0" xyz="0 -0.03 0.07"/>
      <mass value="2.5"/>
      <inertia ixx="0.03" ixy="0" ixz="0" iyy="0.03" iyz="0" izz="0.01"/>
    </inertial>
    <visual>
      <origin rpy="0 0 0" xyz="0 0 0"/>
      <geometry>
        <mesh filename="package://lbr_iiwa_description/meshes/link_4.stl"/>
      </geometry>
      <material name="Orange"/>
    </visual>
    <collision>
      <origin rpy="0 0 0" xyz="0 0 0"/>
      <geometry>
        <mesh filename="package://lbr_iiwa_description/meshes/coarse/link_4.stl"/>
      </geometry>
      <material name="Orange"/>
    </collision>
  </link>
  <!-- joint between link_4 and link_5 -->
  <joint name="lbr_iiwa_joint_5" type="revolute">
    <parent link="lbr_iiwa_link_4"/>
    <child link="lbr_iiwa_link_5"/>
    <origin rpy="0 0 0" xyz="0 0 0.1845"/>
    <axis xyz="0 0 1"/>
    <limit effort="300" lower="-2.96705972839" upper="2.96705972839" velocity="10"/>
    <!-- <safety_controller soft_lower_limit="${-118 * PI / 180}"
           soft_upper_limit="${118 * PI / 180}"
           k_position="${safety_controller_k_pos}"
           k_velocity="${safety_controller_k_vel}"/> -->
    <dynamics damping="0.5"/>
  </joint>
  <link name="lbr_iiwa_link_5">
    <inertial>
      <origin rpy="0 0 0" xyz="0 -0.02 0.08"/>
      <mass value="1.7"/>
      <inertia ixx="0.02" ixy="0" ixz="0" iyy="0.02" iyz="0" izz="0.01"/>
    </inertial>
    <visual>
      <origin rpy="0 0 0" xyz="0 0 0"/>
      <geometry>
        <mesh filename="package://lbr_iiwa_description/meshes/link_5.stl"/>
      </geometry>
      <material name="Orange"/>
    </visual>
    <collision>
      <origin rpy="0 0 0" xyz="0 0 0"/>
      <geometry>
        <mesh filename="package://lbr_iiwa_description/meshes/coarse/link_5.stl"/>
      </geometry>
      <material name="Orange"/>
    </collision>
  </link>
  <!-- joint between link_5 and link_6 -->
  <joint name="lbr_iiwa_joint_6" type="revolute">
    <parent link="lbr_iiwa_link_5"/>
    <child link="lbr_iiwa_link_6"/>
    <origin rpy="0 0 0" xyz="0 -0.0607 0.2155"/>
    <axis xyz="0 1 0"/>
    <limit effort="300" lower="-2.09439510239" upper="2.09439510239" velocity="10"/>
    <!-- <safety_controller soft_lower_limit="${-118 * PI / 180}"
           soft_upper_limit="${118 * PI / 180}"
           k_position="${safety_controller_k_pos}"
           k_velocity="${safety_controller_k_vel}"/> -->
    <dynamics damping="0.5"/>
  </joint>
  <link name="lbr_iiwa_link_6">
    <inertial>
      <origin rpy="0 0 0" xyz="0 0.06 0"/>
      <mass value="1.8"/>
      <inertia ixx="0.01" ixy="0" ixz="0" iyy="0.001" iyz="0" izz="0.01"/>
    </inertial>
    <visual>
      <origin rpy="0 0 0" xyz="0 0 0"/>
      <geometry>
        <mesh filename="package://lbr_iiwa_description/meshes/link_6.stl"/>
      </geometry>
      <material name="Orange"/>
    </visual>
    <collision>
      <origin rpy="0 0 0" xyz="0 0 0"/>
      <geometry>
        <mesh filename="package://lbr_iiwa_description/meshes/coarse/link_6.stl"/>
      </geometry>
      <material name="Orange"/>
    </collision>
  </link>
  <!-- joint between link_6 and link_7 -->
  <joint name="lbr_iiwa_joint_7" type="revolute">
    <parent link="lbr_iiwa_link_6"/>
    <child link="lbr_iiwa_link_7"/>
    <origin rpy="0 0 0" xyz="0 0.0607 0.0809"/>
    <axis xyz="0 0 1"/>
    <limit effort="300" lower="-3.05432619099" upper="3.05432619099" velocity="10"/>
    <!-- <safety_controller soft_lower_limit="${-118 * PI / 180}"
           soft_upper_limit="${118 * PI / 180}"
           k_position="${safety_controller_k_pos}"
           k_velocity="${safety_controller_k_vel}"/> -->
    <dynamics damping="0.5"/>
  </joint>
  <link name="lbr_iiwa_link_7">
    <inertial>
      <origin rpy="0 0 0" xyz="0 0 0.02"/>
      <mass value="0.3"/>
      <inertia ixx="0.001" ixy="0" ixz="0" iyy="0.001" iyz="0" izz="0.001"/>
    </inertial>
    <visual>
      <origin rpy="0 0 0" xyz="0 0 0"/>
      <geometry>
        <mesh filename="package://lbr_iiwa_description/meshes/link_7.stl"/>
      </geometry>
      <material name="Grey"/>
    </visual>
    <collision>
      <origin rpy="0 0 0" xyz="0 0 0"/>
      <geometry>
        <mesh filename="package://lbr_iiwa_description/meshes/coarse/link_7.stl"/>
      </geometry>
      <material name="Grey"/>
    </collision>
  </link>
  
  <!-- joint between link_7 and link_8: cylinder --> <!-- ADDED -->
  <joint name="lbr_iiwa_joint_8" type="fixed">
    <parent link="lbr_iiwa_link_7"/>
    <child link="lbr_iiwa_link_cylinder"/>
    <origin rpy="0 0 0" xyz="0 0 0"/>
  </joint>
  <link name="lbr_iiwa_link_cylinder">
    <inertial>
      <origin rpy="0 0 0" xyz="0 0 0"/>
      <mass value="0.3"/>
      <inertia ixx="0.001" ixy="0" ixz="0" iyy="0.001" iyz="0" izz="0.1"/>
    </inertial>
    <visual>
      <origin rpy="0 0 0" xyz="0 0 0.4"/>
      <geometry>
       <cylinder length="0.8" radius="0.01"/>
      </geometry>
      <material name="Blue"/>
    </visual>
    <collision>
      <origin rpy="0 0 0" xyz="0 0 0.4"/>
      <geometry>
        <cylinder length="0.8" radius="0.01"/>
      </geometry>
    </collision>
  </link>
  
  <!--Extensions -->
  <!-- Link0 -->
  <gazebo reference="lbr_iiwa_link_0">
    <material>Gazebo/Grey</material>
    <mu1>0.2</mu1>
    <mu2>0.2</mu2>
  </gazebo>
  <!-- Link1 -->
  <gazebo reference="lbr_iiwa_link_1">
    <material>Gazebo/Orange</material>
    <mu1>0.2</mu1>
    <mu2>0.2</mu2>
  </gazebo>
  <!-- Link2 -->
  <gazebo reference="lbr_iiwa_link_2">
    <material>Gazebo/Orange</material>
    <mu1>0.2</mu1>
    <mu2>0.2</mu2>
  </gazebo>
  <!-- Link3 -->
  <gazebo reference="lbr_iiwa_link_3">
    <material>Gazebo/Orange</material>
    <mu1>0.2</mu1>
    <mu2>0.2</mu2>
  </gazebo>
  <!-- Link4 -->
  <gazebo reference="lbr_iiwa_link_4">
    <material>Gazebo/Orange</material>
    <mu1>0.2</mu1>
    <mu2>0.2</mu2>
  </gazebo>
  <!-- Link5 -->
  <gazebo reference="lbr_iiwa_link_5">
    <material>Gazebo/Orange</material>
    <mu1>0.2</mu1>
    <mu2>0.2</mu2>
  </gazebo>
  <!-- Link6 -->
  <gazebo reference="lbr_iiwa_link_6">
    <material>Gazebo/Orange</material>
    <mu1>0.2</mu1>
    <mu2>0.2</mu2>
  </gazebo>
  <!-- Link7 -->
  <gazebo reference="lbr_iiwa_link_7">
    <material>Gazebo/Grey</material>
    <mu1>0.2</mu1>
    <mu2>0.2</mu2>
  </gazebo>
  <transmission name="lbr_iiwa_tran_1">
    <type>transmission_interface/SimpleTransmission</type>
    <joint name="lbr_iiwa_joint_1">
      <hardwareInterface>PositionJointInterface</hardwareInterface>
    </joint>
    <actuator name="lbr_iiwa_motor_1">
      <hardwareInterface>PositionJointInterface</hardwareInterface>
      <mechanicalReduction>1</mechanicalReduction>
    </actuator>
  </transmission>
  <transmission name="lbr_iiwa_tran_2">
    <type>transmission_interface/SimpleTransmission</type>
    <joint name="lbr_iiwa_joint_2">
      <hardwareInterface>PositionJointInterface</hardwareInterface>
    </joint>
    <actuator name="lbr_iiwa_motor_2">
      <hardwareInterface>PositionJointInterface</hardwareInterface>
      <mechanicalReduction>1</mechanicalReduction>
    </actuator>
  </transmission>
  <transmission name="lbr_iiwa_tran_3">
    <type>transmission_interface/SimpleTransmission</type>
    <joint name="lbr_iiwa_joint_3">
      <hardwareInterface>PositionJointInterface</hardwareInterface>
    </joint>
    <actuator name="lbr_iiwa_motor_3">
      <hardwareInterface>PositionJointInterface</hardwareInterface>
      <mechanicalReduction>1</mechanicalReduction>
    </actuator>
  </transmission>
  <transmission name="lbr_iiwa_tran_4">
    <type>transmission_interface/SimpleTransmission</type>
    <joint name="lbr_iiwa_joint_4">
      <hardwareInterface>PositionJointInterface</hardwareInterface>
    </joint>
    <actuator name="lbr_iiwa_motor_4">
      <hardwareInterface>PositionJointInterface</hardwareInterface>
      <mechanicalReduction>1</mechanicalReduction>
    </actuator>
  </transmission>
  <transmission name="lbr_iiwa_tran_5">
    <type>transmission_interface/SimpleTransmission</type>
    <joint name="lbr_iiwa_joint_5">
      <hardwareInterface>PositionJointInterface</hardwareInterface>
    </joint>
    <actuator name="lbr_iiwa_motor_5">
      <hardwareInterface>PositionJointInterface</hardwareInterface>
      <mechanicalReduction>1</mechanicalReduction>
    </actuator>
  </transmission>
  <transmission name="lbr_iiwa_tran_6">
    <type>transmission_interface/SimpleTransmission</type>
    <joint name="lbr_iiwa_joint_6">
      <hardwareInterface>PositionJointInterface</hardwareInterface>
    </joint>
    <actuator name="lbr_iiwa_motor_6">
      <hardwareInterface>PositionJointInterface</hardwareInterface>
      <mechanicalReduction>1</mechanicalReduction>
    </actuator>
  </transmission>
  <transmission name="lbr_iiwa_tran_7">
    <type>transmission_interface/SimpleTransmission</type>
    <joint name="lbr_iiwa_joint_7">
      <hardwareInterface>PositionJointInterface</hardwareInterface>
    </joint>
    <actuator name="lbr_iiwa_motor_7">
      <hardwareInterface>PositionJointInterface</hardwareInterface>
      <mechanicalReduction>1</mechanicalReduction>
    </actuator>
  </transmission>
  <!-- schunk_wsg50 gripper -->
  <joint name="schunk_wsg50_fixed_base_joint" type="fixed">
    <origin rpy="0.0 0.0 0.0" xyz="0 0 0.05"/>
    <child link="schunk_wsg50_link_base"/>
    <parent link="lbr_iiwa_link_7"/>
  </joint>
  <link name="schunk_wsg50_link_base">
    <visual>
      <geometry>
        <mesh filename="package://schunk_wsg50/meshes/schunk_wsg50_base_link.stl"/>
      </geometry>
      <material name="Light Grey"/>
    </visual>
    <collision>
      <geometry>
        <mesh filename="package://schunk_wsg50/meshes/schunk_wsg50_base_link_collision.stl"/>
      </geometry>
      <material name="Light Grey"/>
    </collision>
    <inertial>
      <!-- Estimated from reference sheet -->
      <mass value="1.1"/>
      <inertia ixx="1.0" ixy="0.0" ixz="0.0" iyy="1.0" iyz="0.0" izz="1.0"/>
    </inertial>
  </link>
  <joint name="schunk_wsg50_joint_right_jaw" type="prismatic">
    <origin rpy="0 0 0" xyz="0 0 0.0725"/>
    <axis xyz="1 0 0"/>
    <limit effort="59.9" lower="0.0" upper="0.054" velocity="0.042"/>
    <parent link="schunk_wsg50_link_base"/>
    <child link="schunk_wsg50_link_right_jaw"/>
  </joint>
  <link name="schunk_wsg50_link_right_jaw">
    <visual>
      <origin rpy="0 0 0" xyz="0 0 -0.0725"/>
      <geometry>
        <mesh filename="package://schunk_wsg50/meshes/schunk_wsg50_jaw/schunk_wsg50_jaw_1.stl"/>
      </geometry>
      <material name="Grey"/>
    </visual>
    <visual>
      <origin rpy="0 0 0" xyz="0 0 -0.0725"/>
      <geometry>
        <mesh filename="package://schunk_wsg50/meshes/schunk_wsg50_jaw/schunk_wsg50_jaw_2.stl"/>
      </geometry>
      <material name="Grey"/>
    </visual>
    <collision>
      <origin rpy="0 0 0" xyz="0 0 -0.0725"/>
      <geometry>
        <mesh filename="package://schunk_wsg50/meshes/schunk_wsg50_jaw/schunk_wsg50_jaw_1.stl"/>
      </geometry>
      <material name="Grey"/>
    </collision>
    <collision>
      <origin rpy="0 0 0" xyz="0 0 -0.0725"/>
      <geometry>
        <mesh filename="package://schunk_wsg50/meshes/schunk_wsg50_jaw/schunk_wsg50_jaw_2.stl"/>
      </geometry>
      <material name="Grey"/>
    </collision>
    <inertial>
      <!-- Estimated from reference sheet -->
      <mass value="0.05"/>
      <inertia ixx="1.0" ixy="0.0" ixz="0.0" iyy="1.0" iyz="0.0" izz="1.0"/>
    </inertial>
  </link>
  <joint name="schunk_wsg50_joint_left_jaw" type="prismatic">
    <origin rpy="0 0 3.14159265359" xyz="0 0 0.0725"/>
    <axis xyz="1 0 0"/>
    <limit effort="59.9" lower="0.0" upper="0.054" velocity="0.042"/>
    <parent link="schunk_wsg50_link_base"/>
    <child link="schunk_wsg50_link_left_jaw"/>
  </joint>
  <link name="schunk_wsg50_link_left_jaw">
    <visual>
      <origin rpy="0 0 0" xyz="0 0 -0.0725"/>
      <geometry>
        <mesh filename="package://schunk_wsg50/meshes/schunk_wsg50_jaw/schunk_wsg50_jaw_1.stl"/>
      </geometry>
      <material name="Grey"/>
    </visual>
    <visual>
      <origin rpy="0 0 0" xyz="0 0 -0.0725"/>
      <geometry>
        <mesh filename="package://schunk_wsg50/meshes/schunk_wsg50_jaw/schunk_wsg50_jaw_2.stl"/>
      </geometry>
      <material name="Grey"/>
    </visual>
    <collision>
      <origin rpy="0 0 0" xyz="0 0 -0.0725"/>
      <geometry>
        <mesh filename="package://schunk_wsg50/meshes/schunk_wsg50_jaw/schunk_wsg50_jaw_1.stl"/>
      </geometry>
      <material name="Grey"/>
    </collision>
    <collision>
      <origin rpy="0 0 0" xyz="0 0 -0.0725"/>
      <geometry>
        <mesh filename="package://schunk_wsg50/meshes/schunk_wsg50_jaw/schunk_wsg50_jaw_2.stl"/>
      </geometry>
      <material name="Grey"/>
    </collision>
    <inertial>
      <!-- Estimated from reference sheet -->
      <mass value="0.05"/>
      <inertia ixx="1.0" ixy="0.0" ixz="0.0" iyy="1.0" iyz="0.0" izz="1.0"/>
    </inertial>
  </link>
  <joint name="schunk_wsg50_palm_joint" type="fixed">
    <origin rpy="0 0 0" xyz="0.0 0.0 0.0725"/>
    <parent link="schunk_wsg50_link_base"/>
    <child link="schunk_wsg50_link_palm"/>
  </joint>
  <link name="schunk_wsg50_link_palm"/>
  <!--Extensions -->
  <!-- Link0 -->
  <gazebo reference="schunk_wsg50_link_base">
    <material>Gazebo/Grey</material>
    <mu1>0.2</mu1>
    <mu2>0.2</mu2>
  </gazebo>
  <gazebo reference="schunk_wsg50_link_right_jaw">
    <material>Gazebo/DarkGrey</material>
    <mu1>0.2</mu1>
    <mu2>0.2</mu2>
  </gazebo>
  <gazebo reference="schunk_wsg50_link_left_jaw">
    <material>Gazebo/DarkGrey</material>
    <mu1>0.2</mu1>
    <mu2>0.2</mu2>
  </gazebo>
  <transmission name="schunk_wsg50_tran_right_jaw">
    <type>transmission_interface/SimpleTransmission</type>
    <joint name="schunk_wsg50_joint_right_jaw">
      <hardwareInterface>PositionJointInterface</hardwareInterface>
    </joint>
    <actuator name="schunk_wsg50_motor_right_jaw">
      <hardwareInterface>PositionJointInterface</hardwareInterface>
      <mechanicalReduction>1</mechanicalReduction>
    </actuator>
  </transmission>
  <transmission name="schunk_wsg50_tran_left_jaw">
    <type>transmission_interface/SimpleTransmission</type>
    <joint name="schunk_wsg50_joint_left_jaw">
      <hardwareInterface>PositionJointInterface</hardwareInterface>
    </joint>
    <actuator name="schunk_wsg50_motor_left_jaw">
      <hardwareInterface>PositionJointInterface</hardwareInterface>
      <mechanicalReduction>1</mechanicalReduction>
    </actuator>
  </transmission>
  <!-- pan tilt mast -->
  <joint name="pan_tilt_mast_fixed_base_joint" type="fixed">
    <child link="pan_tilt_mast_link"/>
    <parent link="miiwa_link_mast_mount"/>
  </joint>
  <link name="pan_tilt_mast_link">
    <visual>
      <origin rpy="0 0 0" xyz="0 0 0.25"/>
      <geometry>
        <box size="0.07 0.07 0.5"/>
      </geometry>
      <material name="Light Grey"/>
    </visual>
    <collision>
      <origin rpy="0 0 0" xyz="0 0 0.25"/>
      <geometry>
        <box size="0.07 0.07 0.5"/>
      </geometry>
      <material name="Light Grey"/>
    </collision>
    <inertial>
      <!--estimated from geometry and density of alumium-->
      <origin rpy="0 0 0" xyz="0 0 0.25"/>
      <mass value="6.3"/>
      <inertia ixx="1.0" ixy="0.0" ixz="0.0" iyy="1.0" iyz="0.0" izz="1.0"/>
    </inertial>
  </link>
  <joint name="pan_tilt_mast_joint_mount" type="fixed">
    <origin rpy="0 0 0" xyz="0.0 0.0 0.5"/>
    <parent link="pan_tilt_mast_link"/>
    <child link="pan_tilt_mast_link_mount"/>
  </joint>
  <link name="pan_tilt_mast_link_mount"/>
  <gazebo reference="pan_tilt_mast_link">
    <material>Gazebo/Grey</material>
    <mu1>0.2</mu1>
    <mu2>0.2</mu2>
  </gazebo>
  <!-- schunk_pw70 pan tilt mast -->
  <joint name="schunk_pw70_fixed_base_joint" type="fixed">
    <origin rpy="0.0 0.0 0.0" xyz="0 0 0.0"/>
    <child link="schunk_pw70_link_base"/>
    <parent link="pan_tilt_mast_link_mount"/>
  </joint>
  <link name="schunk_pw70_link_base">
    <visual>
      <origin rpy="0 3.14159265359 0" xyz="0. 0 0.093"/>
      <geometry>
        <mesh filename="package://schunk_pw70/meshes/schunk_pw_70_pan_link.stl"/>
      </geometry>
      <material name="Light Grey"/>
    </visual>
    <collision>
      <origin rpy="0 3.14159265359 0" xyz="0 0 0.093"/>
      <geometry>
        <mesh filename="package://schunk_pw70/meshes/schunk_pw_70_pan_link_collision.stl"/>
      </geometry>
      <material name="Light Grey"/>
    </collision>
    <inertial>
      <!-- Estimated by volume approx -->
      <mass value="0.187"/>
      <inertia ixx="1.0" ixy="0.0" ixz="0.0" iyy="1.0" iyz="0.0" izz="1.0"/>
    </inertial>
  </link>
  <joint name="schunk_pw70_joint_pan" type="revolute">
    <origin rpy="0 0 0" xyz="0 0 0.057"/>
    <axis xyz="0 0 1"/>
    <limit effort="1.9" lower="-3.14159265359" upper="3.14159265359" velocity="6.26573201466"/>
    <parent link="schunk_pw70_link_base"/>
    <child link="schunk_pw70_link_pan"/>
  </joint>
  <link name="schunk_pw70_link_pan">
    <visual>
      <origin rpy="0 3.14159265359 0" xyz="0 0 0.037"/>
      <geometry>
        <mesh filename="package://schunk_pw70/meshes/schunk_pw_70_tilt_link.stl"/>
      </geometry>
      <material name="Light Grey"/>
    </visual>
    <collision>
      <origin rpy="0 3.14159265359 0" xyz="0 0 0.037"/>
      <geometry>
        <mesh filename="package://schunk_pw70/meshes/schunk_pw_70_tilt_link_collision.stl"/>
      </geometry>
      <material name="Light Grey"/>
    </collision>
    <inertial>
      <!-- Estimated by volume approx -->
      <mass value="1.126"/>
      <inertia ixx="1.0" ixy="0.0" ixz="0.0" iyy="1.0" iyz="0.0" izz="1.0"/>
    </inertial>
  </link>
  <joint name="schunk_pw70_joint_tilt" type="revolute">
    <origin rpy="0 0 0" xyz="0 0 0.037"/>
    <axis xyz="1 0 0"/>
    <limit effort="11.9" lower="-2.07694180987" upper="2.07694180987" velocity="4.17133691227"/>
    <parent link="schunk_pw70_link_pan"/>
    <child link="schunk_pw70_link_tilt"/>
  </joint>
  <link name="schunk_pw70_link_tilt">
    <visual>
      <origin rpy="0 3.14159265359 0" xyz="0 0 0.0"/>
      <geometry>
        <mesh filename="package://schunk_pw70/meshes/schunk_pw_70_base_link.stl"/>
      </geometry>
      <material name="Light Grey"/>
    </visual>
    <collision>
      <origin rpy="0 3.14159265359 0" xyz="0 0 0.0"/>
      <geometry>
        <mesh filename="package://schunk_pw70/meshes/schunk_pw_70_base_link_collision.stl"/>
      </geometry>
      <material name="Light Grey"/>
    </collision>
    <inertial>
      <!-- Estimated by volume approx -->
      <mass value="0.487"/>
      <inertia ixx="1.0" ixy="0.0" ixz="0.0" iyy="1.0" iyz="0.0" izz="1.0"/>
    </inertial>
  </link>
  <joint name="schunk_pw70_mount_joint" type="fixed">
    <origin rpy="0 0 0" xyz="0.0 0.0 0.07"/>
    <parent link="schunk_pw70_link_tilt"/>
    <child link="schunk_pw70_link_mount"/>
  </joint>
  <link name="schunk_pw70_link_mount"/>
  <!--Extensions -->
  <!-- Link0 -->
  <gazebo reference="schunk_pw70_link_base">
    <material>Gazebo/Grey</material>
    <mu1>0.2</mu1>
    <mu2>0.2</mu2>
  </gazebo>
  <gazebo reference="schunk_pw70_link_pan">
    <material>Gazebo/Grey</material>
    <mu1>0.2</mu1>
    <mu2>0.2</mu2>
  </gazebo>
  <gazebo reference="schunk_pw70_link_tilt">
    <material>Gazebo/Grey</material>
    <mu1>0.2</mu1>
    <mu2>0.2</mu2>
  </gazebo>
  <transmission name="schunk_pw70_tran_pan">
    <type>transmission_interface/SimpleTransmission</type>
    <joint name="schunk_pw70_joint_pan">
      <hardwareInterface>PositionJointInterface</hardwareInterface>
    </joint>
    <actuator name="schunk_pw70_motor_pan">
      <hardwareInterface>PositionJointInterface</hardwareInterface>
      <mechanicalReduction>1</mechanicalReduction>
    </actuator>
  </transmission>
  <transmission name="schunk_pw70_tran_tilt">
    <type>transmission_interface/SimpleTransmission</type>
    <joint name="schunk_pw70_joint_tilt">
      <hardwareInterface>PositionJointInterface</hardwareInterface>
    </joint>
    <actuator name="schunk_pw70_motor_tilt">
      <hardwareInterface>PositionJointInterface</hardwareInterface>
      <mechanicalReduction>1</mechanicalReduction>
    </actuator>
  </transmission>
  <!-- cameras -->
  <joint name="mako_3d_hand_left_fixed_base_joint" type="fixed">
    <origin rpy="0.0 0.0 0.0" xyz="-0.025 0.0415 -0.02"/>
    <child link="mako_3d_hand_left_link"/>
    <parent link="schunk_wsg50_link_palm"/>
  </joint>
  <link name="mako_3d_hand_left_link">
    <visual>
      <geometry>
        <mesh filename="package://mako_3d/meshes/mako_3d_link/back.stl"/>
      </geometry>
      <material name="Grey"/>
    </visual>
    <visual>
      <geometry>
        <mesh filename="package://mako_3d/meshes/mako_3d_link/bottom.stl"/>
      </geometry>
      <material name="Light Grey"/>
    </visual>
    <visual>
      <geometry>
        <mesh filename="package://mako_3d/meshes/mako_3d_link/cover.stl"/>
      </geometry>
      <material name="Red"/>
    </visual>
    <visual>
      <geometry>
        <mesh filename="package://mako_3d/meshes/mako_3d_link/ethernet.stl"/>
      </geometry>
      <material name="Light Grey"/>
    </visual>
    <visual>
      <geometry>
        <mesh filename="package://mako_3d/meshes/mako_3d_link/front.stl"/>
      </geometry>
      <material name="Light Grey"/>
    </visual>
    <visual>
      <geometry>
        <mesh filename="package://mako_3d/meshes/mako_3d_link/lens.stl"/>
      </geometry>
      <material name="Light Grey"/>
    </visual>
    <visual>
      <geometry>
        <mesh filename="package://mako_3d/meshes/mako_3d_link/power.stl"/>
      </geometry>
      <material name="Light Grey"/>
    </visual>
    <collision>
      <geometry>
        <mesh filename="package://mako_3d/meshes/mako_3d_link/back.stl"/>
      </geometry>
      <material name="Light Grey"/>
    </collision>
    <collision>
      <geometry>
        <mesh filename="package://mako_3d/meshes/mako_3d_link/bottom.stl"/>
      </geometry>
      <material name="Light Grey"/>
    </collision>
    <collision>
      <geometry>
        <mesh filename="package://mako_3d/meshes/mako_3d_link/cover.stl"/>
      </geometry>
      <material name="Red"/>
    </collision>
    <collision>
      <geometry>
        <mesh filename="package://mako_3d/meshes/mako_3d_link/ethernet.stl"/>
      </geometry>
      <material name="Light Grey"/>
    </collision>
    <collision>
      <geometry>
        <mesh filename="package://mako_3d/meshes/mako_3d_link/front.stl"/>
      </geometry>
      <material name="Light Grey"/>
    </collision>
    <collision>
      <geometry>
        <mesh filename="package://mako_3d/meshes/mako_3d_link/lens.stl"/>
      </geometry>
      <material name="Light Grey"/>
    </collision>
    <collision>
      <geometry>
        <mesh filename="package://mako_3d/meshes/mako_3d_link/power.stl"/>
      </geometry>
      <material name="Light Grey"/>
    </collision>
    <inertial>
      <!-- Estimated from reference sheet -->
      <mass value="0.08"/>
      <inertia ixx="1.0" ixy="0.0" ixz="0.0" iyy="1.0" iyz="0.0" izz="1.0"/>
    </inertial>
  </link>
  <!--Extensions -->
  <joint name="mako_3d_hand_left_gazebo_optical_joint" type="fixed">
    <child link="mako_3d_hand_left_gazebo_optical_link"/>
    <parent link="mako_3d_hand_left_link"/>
    <origin rpy="0 -1.57079632679 -1.57079632679" xyz="0 0 0"/>
  </joint>
  <link name="mako_3d_hand_left_gazebo_optical_link"/>
  <gazebo reference="mako_3d_hand_left_link">
    <material>Gazebo/DarkGrey</material>
    <mu1>0.2</mu1>
    <mu2>0.2</mu2>
  </gazebo>
  <gazebo reference="mako_3d_hand_left_gazebo_optical_link">
    <sensor name="mako_3d_hand_left" type="camera">
      <update_rate>10.0</update_rate>
      <camera name="mako_3d_hand_left">
        <horizontal_fov>1.3962634</horizontal_fov>
        <image>
          <width>1292</width>
          <height>964</height>
          <format>R8G8B8</format>
        </image>
      </camera>
      <plugin filename="libgazebo_ros_camera.so" name="camera_controller">
        <alwaysOn>true</alwaysOn>
        <updateRate>10.0</updateRate>
        <cameraName>mako_3d_hand_left</cameraName>
        <imageTopicName>image_raw</imageTopicName>
        <cameraInfoTopicName>camera_info</cameraInfoTopicName>
        <frameName>mako_3d_hand_left_gazebo_optical_link</frameName>
      </plugin>
    </sensor>
  </gazebo>
  <joint name="mako_3d_hand_right_fixed_base_joint" type="fixed">
    <origin rpy="0.0 0.0 0.0" xyz="0.05 0 0"/>
    <child link="mako_3d_hand_right_link"/>
    <parent link="mako_3d_hand_left_link"/>
  </joint>
  <link name="mako_3d_hand_right_link">
    <visual>
      <geometry>
        <mesh filename="package://mako_3d/meshes/mako_3d_link/back.stl"/>
      </geometry>
      <material name="Grey"/>
    </visual>
    <visual>
      <geometry>
        <mesh filename="package://mako_3d/meshes/mako_3d_link/bottom.stl"/>
      </geometry>
      <material name="Light Grey"/>
    </visual>
    <visual>
      <geometry>
        <mesh filename="package://mako_3d/meshes/mako_3d_link/cover.stl"/>
      </geometry>
      <material name="Red"/>
    </visual>
    <visual>
      <geometry>
        <mesh filename="package://mako_3d/meshes/mako_3d_link/ethernet.stl"/>
      </geometry>
      <material name="Light Grey"/>
    </visual>
    <visual>
      <geometry>
        <mesh filename="package://mako_3d/meshes/mako_3d_link/front.stl"/>
      </geometry>
      <material name="Light Grey"/>
    </visual>
    <visual>
      <geometry>
        <mesh filename="package://mako_3d/meshes/mako_3d_link/lens.stl"/>
      </geometry>
      <material name="Light Grey"/>
    </visual>
    <visual>
      <geometry>
        <mesh filename="package://mako_3d/meshes/mako_3d_link/power.stl"/>
      </geometry>
      <material name="Light Grey"/>
    </visual>
    <collision>
      <geometry>
        <mesh filename="package://mako_3d/meshes/mako_3d_link/back.stl"/>
      </geometry>
      <material name="Light Grey"/>
    </collision>
    <collision>
      <geometry>
        <mesh filename="package://mako_3d/meshes/mako_3d_link/bottom.stl"/>
      </geometry>
      <material name="Light Grey"/>
    </collision>
    <collision>
      <geometry>
        <mesh filename="package://mako_3d/meshes/mako_3d_link/cover.stl"/>
      </geometry>
      <material name="Red"/>
    </collision>
    <collision>
      <geometry>
        <mesh filename="package://mako_3d/meshes/mako_3d_link/ethernet.stl"/>
      </geometry>
      <material name="Light Grey"/>
    </collision>
    <collision>
      <geometry>
        <mesh filename="package://mako_3d/meshes/mako_3d_link/front.stl"/>
      </geometry>
      <material name="Light Grey"/>
    </collision>
    <collision>
      <geometry>
        <mesh filename="package://mako_3d/meshes/mako_3d_link/lens.stl"/>
      </geometry>
      <material name="Light Grey"/>
    </collision>
    <collision>
      <geometry>
        <mesh filename="package://mako_3d/meshes/mako_3d_link/power.stl"/>
      </geometry>
      <material name="Light Grey"/>
    </collision>
    <inertial>
      <!-- Estimated from reference sheet -->
      <mass value="0.08"/>
      <inertia ixx="1.0" ixy="0.0" ixz="0.0" iyy="1.0" iyz="0.0" izz="1.0"/>
    </inertial>
  </link>
  <!--Extensions -->
  <joint name="mako_3d_hand_right_gazebo_optical_joint" type="fixed">
    <child link="mako_3d_hand_right_gazebo_optical_link"/>
    <parent link="mako_3d_hand_right_link"/>
    <origin rpy="0 -1.57079632679 -1.57079632679" xyz="0 0 0"/>
  </joint>
  <link name="mako_3d_hand_right_gazebo_optical_link"/>
  <gazebo reference="mako_3d_hand_right_link">
    <material>Gazebo/DarkGrey</material>
    <mu1>0.2</mu1>
    <mu2>0.2</mu2>
  </gazebo>
  <gazebo reference="mako_3d_hand_right_gazebo_optical_link">
    <sensor name="mako_3d_hand_right" type="camera">
      <update_rate>10.0</update_rate>
      <camera name="mako_3d_hand_right">
        <horizontal_fov>1.3962634</horizontal_fov>
        <image>
          <width>1292</width>
          <height>964</height>
          <format>R8G8B8</format>
        </image>
      </camera>
      <plugin filename="libgazebo_ros_camera.so" name="camera_controller">
        <alwaysOn>true</alwaysOn>
        <updateRate>10.0</updateRate>
        <cameraName>mako_3d_hand_right</cameraName>
        <imageTopicName>image_raw</imageTopicName>
        <cameraInfoTopicName>camera_info</cameraInfoTopicName>
        <frameName>mako_3d_hand_right_gazebo_optical_link</frameName>
      </plugin>
    </sensor>
  </gazebo>
  <joint name="mako_3d_mast_left_fixed_base_joint" type="fixed">
    <origin rpy="1.57079632679 0.0 0.0" xyz="0.025 0.0 0.0145"/>
    <child link="mako_3d_mast_left_link"/>
    <parent link="schunk_pw70_link_mount"/>
  </joint>
  <link name="mako_3d_mast_left_link">
    <visual>
      <geometry>
        <mesh filename="package://mako_3d/meshes/mako_3d_link/back.stl"/>
      </geometry>
      <material name="Grey"/>
    </visual>
    <visual>
      <geometry>
        <mesh filename="package://mako_3d/meshes/mako_3d_link/bottom.stl"/>
      </geometry>
      <material name="Light Grey"/>
    </visual>
    <visual>
      <geometry>
        <mesh filename="package://mako_3d/meshes/mako_3d_link/cover.stl"/>
      </geometry>
      <material name="Red"/>
    </visual>
    <visual>
      <geometry>
        <mesh filename="package://mako_3d/meshes/mako_3d_link/ethernet.stl"/>
      </geometry>
      <material name="Light Grey"/>
    </visual>
    <visual>
      <geometry>
        <mesh filename="package://mako_3d/meshes/mako_3d_link/front.stl"/>
      </geometry>
      <material name="Light Grey"/>
    </visual>
    <visual>
      <geometry>
        <mesh filename="package://mako_3d/meshes/mako_3d_link/lens.stl"/>
      </geometry>
      <material name="Light Grey"/>
    </visual>
    <visual>
      <geometry>
        <mesh filename="package://mako_3d/meshes/mako_3d_link/power.stl"/>
      </geometry>
      <material name="Light Grey"/>
    </visual>
    <collision>
      <geometry>
        <mesh filename="package://mako_3d/meshes/mako_3d_link/back.stl"/>
      </geometry>
      <material name="Light Grey"/>
    </collision>
    <collision>
      <geometry>
        <mesh filename="package://mako_3d/meshes/mako_3d_link/bottom.stl"/>
      </geometry>
      <material name="Light Grey"/>
    </collision>
    <collision>
      <geometry>
        <mesh filename="package://mako_3d/meshes/mako_3d_link/cover.stl"/>
      </geometry>
      <material name="Red"/>
    </collision>
    <collision>
      <geometry>
        <mesh filename="package://mako_3d/meshes/mako_3d_link/ethernet.stl"/>
      </geometry>
      <material name="Light Grey"/>
    </collision>
    <collision>
      <geometry>
        <mesh filename="package://mako_3d/meshes/mako_3d_link/front.stl"/>
      </geometry>
      <material name="Light Grey"/>
    </collision>
    <collision>
      <geometry>
        <mesh filename="package://mako_3d/meshes/mako_3d_link/lens.stl"/>
      </geometry>
      <material name="Light Grey"/>
    </collision>
    <collision>
      <geometry>
        <mesh filename="package://mako_3d/meshes/mako_3d_link/power.stl"/>
      </geometry>
      <material name="Light Grey"/>
    </collision>
    <inertial>
      <!-- Estimated from reference sheet -->
      <mass value="0.08"/>
      <inertia ixx="1.0" ixy="0.0" ixz="0.0" iyy="1.0" iyz="0.0" izz="1.0"/>
    </inertial>
  </link>
  <!--Extensions -->
  <joint name="mako_3d_mast_left_gazebo_optical_joint" type="fixed">
    <child link="mako_3d_mast_left_gazebo_optical_link"/>
    <parent link="mako_3d_mast_left_link"/>
    <origin rpy="0 -1.57079632679 -1.57079632679" xyz="0 0 0"/>
  </joint>
  <link name="mako_3d_mast_left_gazebo_optical_link"/>
  <gazebo reference="mako_3d_mast_left_link">
    <material>Gazebo/DarkGrey</material>
    <mu1>0.2</mu1>
    <mu2>0.2</mu2>
  </gazebo>
  <gazebo reference="mako_3d_mast_left_gazebo_optical_link">
    <sensor name="mako_3d_mast_left" type="camera">
      <update_rate>10.0</update_rate>
      <camera name="mako_3d_mast_left">
        <horizontal_fov>1.3962634</horizontal_fov>
        <image>
          <width>1292</width>
          <height>964</height>
          <format>R8G8B8</format>
        </image>
      </camera>
      <plugin filename="libgazebo_ros_camera.so" name="camera_controller">
        <alwaysOn>true</alwaysOn>
        <updateRate>10.0</updateRate>
        <cameraName>mako_3d_mast_left</cameraName>
        <imageTopicName>image_raw</imageTopicName>
        <cameraInfoTopicName>camera_info</cameraInfoTopicName>
        <frameName>mako_3d_mast_left_gazebo_optical_link</frameName>
      </plugin>
    </sensor>
  </gazebo>
  <joint name="mako_3d_mast_right_fixed_base_joint" type="fixed">
    <origin rpy="0.0 0.0 0.0" xyz="-0.05 0 0"/>
    <child link="mako_3d_mast_right_link"/>
    <parent link="mako_3d_mast_left_link"/>
  </joint>
  <link name="mako_3d_mast_right_link">
    <visual>
      <geometry>
        <mesh filename="package://mako_3d/meshes/mako_3d_link/back.stl"/>
      </geometry>
      <material name="Grey"/>
    </visual>
    <visual>
      <geometry>
        <mesh filename="package://mako_3d/meshes/mako_3d_link/bottom.stl"/>
      </geometry>
      <material name="Light Grey"/>
    </visual>
    <visual>
      <geometry>
        <mesh filename="package://mako_3d/meshes/mako_3d_link/cover.stl"/>
      </geometry>
      <material name="Red"/>
    </visual>
    <visual>
      <geometry>
        <mesh filename="package://mako_3d/meshes/mako_3d_link/ethernet.stl"/>
      </geometry>
      <material name="Light Grey"/>
    </visual>
    <visual>
      <geometry>
        <mesh filename="package://mako_3d/meshes/mako_3d_link/front.stl"/>
      </geometry>
      <material name="Light Grey"/>
    </visual>
    <visual>
      <geometry>
        <mesh filename="package://mako_3d/meshes/mako_3d_link/lens.stl"/>
      </geometry>
      <material name="Light Grey"/>
    </visual>
    <visual>
      <geometry>
        <mesh filename="package://mako_3d/meshes/mako_3d_link/power.stl"/>
      </geometry>
      <material name="Light Grey"/>
    </visual>
    <collision>
      <geometry>
        <mesh filename="package://mako_3d/meshes/mako_3d_link/back.stl"/>
      </geometry>
      <material name="Light Grey"/>
    </collision>
    <collision>
      <geometry>
        <mesh filename="package://mako_3d/meshes/mako_3d_link/bottom.stl"/>
      </geometry>
      <material name="Light Grey"/>
    </collision>
    <collision>
      <geometry>
        <mesh filename="package://mako_3d/meshes/mako_3d_link/cover.stl"/>
      </geometry>
      <material name="Red"/>
    </collision>
    <collision>
      <geometry>
        <mesh filename="package://mako_3d/meshes/mako_3d_link/ethernet.stl"/>
      </geometry>
      <material name="Light Grey"/>
    </collision>
    <collision>
      <geometry>
        <mesh filename="package://mako_3d/meshes/mako_3d_link/front.stl"/>
      </geometry>
      <material name="Light Grey"/>
    </collision>
    <collision>
      <geometry>
        <mesh filename="package://mako_3d/meshes/mako_3d_link/lens.stl"/>
      </geometry>
      <material name="Light Grey"/>
    </collision>
    <collision>
      <geometry>
        <mesh filename="package://mako_3d/meshes/mako_3d_link/power.stl"/>
      </geometry>
      <material name="Light Grey"/>
    </collision>
    <inertial>
      <!-- Estimated from reference sheet -->
      <mass value="0.08"/>
      <inertia ixx="1.0" ixy="0.0" ixz="0.0" iyy="1.0" iyz="0.0" izz="1.0"/>
    </inertial>
  </link>
  <!--Extensions -->
  <joint name="mako_3d_mast_right_gazebo_optical_joint" type="fixed">
    <child link="mako_3d_mast_right_gazebo_optical_link"/>
    <parent link="mako_3d_mast_right_link"/>
    <origin rpy="0 -1.57079632679 -1.57079632679" xyz="0 0 0"/>
  </joint>
  <link name="mako_3d_mast_right_gazebo_optical_link"/>
  <gazebo reference="mako_3d_mast_right_link">
    <material>Gazebo/DarkGrey</material>
    <mu1>0.2</mu1>
    <mu2>0.2</mu2>
  </gazebo>
  <gazebo reference="mako_3d_mast_right_gazebo_optical_link">
    <sensor name="mako_3d_mast_right" type="camera">
      <update_rate>10.0</update_rate>
      <camera name="mako_3d_mast_right">
        <horizontal_fov>1.3962634</horizontal_fov>
        <image>
          <width>1292</width>
          <height>964</height>
          <format>R8G8B8</format>
        </image>
      </camera>
      <plugin filename="libgazebo_ros_camera.so" name="camera_controller">
        <alwaysOn>true</alwaysOn>
        <updateRate>10.0</updateRate>
        <cameraName>mako_3d_mast_right</cameraName>
        <imageTopicName>image_raw</imageTopicName>
        <cameraInfoTopicName>camera_info</cameraInfoTopicName>
        <frameName>mako_3d_mast_right_gazebo_optical_link</frameName>
      </plugin>
    </sensor>
  </gazebo>
</robot>

